2019-12-14 23:28:45,803 ERROR: Exception on /contact [GET] [in c:\users\kusuma mulpuru\microblog\venv\lib\site-packages\flask\app.py:1891]
Traceback (most recent call last):
  File "c:\users\kusuma mulpuru\microblog\venv\lib\site-packages\flask\app.py", line 2446, in wsgi_app
    response = self.full_dispatch_request()
  File "c:\users\kusuma mulpuru\microblog\venv\lib\site-packages\flask\app.py", line 1951, in full_dispatch_request
    rv = self.handle_user_exception(e)
  File "c:\users\kusuma mulpuru\microblog\venv\lib\site-packages\flask\app.py", line 1820, in handle_user_exception
    reraise(exc_type, exc_value, tb)
  File "c:\users\kusuma mulpuru\microblog\venv\lib\site-packages\flask\_compat.py", line 39, in reraise
    raise value
  File "c:\users\kusuma mulpuru\microblog\venv\lib\site-packages\flask\app.py", line 1949, in full_dispatch_request
    rv = self.dispatch_request()
  File "c:\users\kusuma mulpuru\microblog\venv\lib\site-packages\flask\app.py", line 1935, in dispatch_request
    return self.view_functions[rule.endpoint](**req.view_args)
  File "C:\Users\kusuma Mulpuru\microblog\app\routes.py", line 203, in contact
    return render_template('contact.html', form=form)
  File "c:\users\kusuma mulpuru\microblog\venv\lib\site-packages\flask\templating.py", line 140, in render_template
    ctx.app,
  File "c:\users\kusuma mulpuru\microblog\venv\lib\site-packages\flask\templating.py", line 120, in _render
    rv = template.render(context)
  File "c:\users\kusuma mulpuru\microblog\venv\lib\site-packages\jinja2\asyncsupport.py", line 76, in render
    return original_render(self, *args, **kwargs)
  File "c:\users\kusuma mulpuru\microblog\venv\lib\site-packages\jinja2\environment.py", line 1008, in render
    return self.environment.handle_exception(exc_info, True)
  File "c:\users\kusuma mulpuru\microblog\venv\lib\site-packages\jinja2\environment.py", line 780, in handle_exception
    reraise(exc_type, exc_value, tb)
  File "c:\users\kusuma mulpuru\microblog\venv\lib\site-packages\jinja2\_compat.py", line 37, in reraise
    raise value.with_traceback(tb)
  File "C:\Users\kusuma Mulpuru\microblog\app\templates\contact.html", line 1, in top-level template code
    {% extends "base.html" %}
  File "c:\users\kusuma mulpuru\microblog\venv\lib\site-packages\jinja2\environment.py", line 1005, in render
    return concat(self.root_render_func(self.new_context(vars)))
  File "C:\Users\kusuma Mulpuru\microblog\app\templates\contact.html", line 14, in root
    <p>
  File "C:\Users\kusuma Mulpuru\microblog\app\templates\base.html", line 14, in root
    <span class="icon-bar"></span>
  File "c:\users\kusuma mulpuru\microblog\venv\lib\site-packages\flask_bootstrap\templates\bootstrap\base.html", line 10, in root
    <meta name="viewport" content="width=device-width, initial-scale=1.0">
  File "c:\users\kusuma mulpuru\microblog\venv\lib\site-packages\flask_bootstrap\templates\bootstrap\base.html", line 20, in block_doc
    {% block body -%}
  File "c:\users\kusuma mulpuru\microblog\venv\lib\site-packages\flask_bootstrap\templates\bootstrap\base.html", line 39, in block_html
  File "c:\users\kusuma mulpuru\microblog\venv\lib\site-packages\flask_bootstrap\templates\bootstrap\base.html", line 92, in block_body
  File "C:\Users\kusuma Mulpuru\microblog\app\templates\contact.html", line 35, in block_content
  File "c:\users\kusuma mulpuru\microblog\venv\lib\site-packages\jinja2\runtime.py", line 262, in call
    return __obj(*args, **kwargs)
  File "c:\users\kusuma mulpuru\microblog\venv\lib\site-packages\jinja2\runtime.py", line 630, in _fail_with_undefined_error
    raise self._undefined_exception(hint)
jinja2.exceptions.UndefinedError: 'app.forms.ContactForm object' has no attribute 'contactkInfo'
2019-12-14 23:31:08,853 INFO: Microblog startup [in C:\Users\kusuma Mulpuru\microblog\app\__init__.py:49]
2019-12-14 23:32:00,571 ERROR: Exception on /contact [POST] [in c:\users\kusuma mulpuru\microblog\venv\lib\site-packages\flask\app.py:1891]
Traceback (most recent call last):
  File "c:\users\kusuma mulpuru\microblog\venv\lib\site-packages\sqlalchemy\engine\base.py", line 1246, in _execute_context
    cursor, statement, parameters, context
  File "c:\users\kusuma mulpuru\microblog\venv\lib\site-packages\sqlalchemy\engine\default.py", line 581, in do_execute
    cursor.execute(statement, parameters)
sqlite3.OperationalError: no such table: contact

The above exception was the direct cause of the following exception:

Traceback (most recent call last):
  File "c:\users\kusuma mulpuru\microblog\venv\lib\site-packages\flask\app.py", line 2446, in wsgi_app
    response = self.full_dispatch_request()
  File "c:\users\kusuma mulpuru\microblog\venv\lib\site-packages\flask\app.py", line 1951, in full_dispatch_request
    rv = self.handle_user_exception(e)
  File "c:\users\kusuma mulpuru\microblog\venv\lib\site-packages\flask\app.py", line 1820, in handle_user_exception
    reraise(exc_type, exc_value, tb)
  File "c:\users\kusuma mulpuru\microblog\venv\lib\site-packages\flask\_compat.py", line 39, in reraise
    raise value
  File "c:\users\kusuma mulpuru\microblog\venv\lib\site-packages\flask\app.py", line 1949, in full_dispatch_request
    rv = self.dispatch_request()
  File "c:\users\kusuma mulpuru\microblog\venv\lib\site-packages\flask\app.py", line 1935, in dispatch_request
    return self.view_functions[rule.endpoint](**req.view_args)
  File "C:\Users\kusuma Mulpuru\microblog\app\routes.py", line 200, in contact
    db.session.commit()
  File "c:\users\kusuma mulpuru\microblog\venv\lib\site-packages\sqlalchemy\orm\scoping.py", line 162, in do
    return getattr(self.registry(), name)(*args, **kwargs)
  File "c:\users\kusuma mulpuru\microblog\venv\lib\site-packages\sqlalchemy\orm\session.py", line 1027, in commit
    self.transaction.commit()
  File "c:\users\kusuma mulpuru\microblog\venv\lib\site-packages\sqlalchemy\orm\session.py", line 494, in commit
    self._prepare_impl()
  File "c:\users\kusuma mulpuru\microblog\venv\lib\site-packages\sqlalchemy\orm\session.py", line 473, in _prepare_impl
    self.session.flush()
  File "c:\users\kusuma mulpuru\microblog\venv\lib\site-packages\sqlalchemy\orm\session.py", line 2470, in flush
    self._flush(objects)
  File "c:\users\kusuma mulpuru\microblog\venv\lib\site-packages\sqlalchemy\orm\session.py", line 2608, in _flush
    transaction.rollback(_capture_exception=True)
  File "c:\users\kusuma mulpuru\microblog\venv\lib\site-packages\sqlalchemy\util\langhelpers.py", line 68, in __exit__
    compat.reraise(exc_type, exc_value, exc_tb)
  File "c:\users\kusuma mulpuru\microblog\venv\lib\site-packages\sqlalchemy\util\compat.py", line 153, in reraise
    raise value
  File "c:\users\kusuma mulpuru\microblog\venv\lib\site-packages\sqlalchemy\orm\session.py", line 2568, in _flush
    flush_context.execute()
  File "c:\users\kusuma mulpuru\microblog\venv\lib\site-packages\sqlalchemy\orm\unitofwork.py", line 422, in execute
    rec.execute(self)
  File "c:\users\kusuma mulpuru\microblog\venv\lib\site-packages\sqlalchemy\orm\unitofwork.py", line 589, in execute
    uow,
  File "c:\users\kusuma mulpuru\microblog\venv\lib\site-packages\sqlalchemy\orm\persistence.py", line 245, in save_obj
    insert,
  File "c:\users\kusuma mulpuru\microblog\venv\lib\site-packages\sqlalchemy\orm\persistence.py", line 1137, in _emit_insert_statements
    statement, params
  File "c:\users\kusuma mulpuru\microblog\venv\lib\site-packages\sqlalchemy\engine\base.py", line 982, in execute
    return meth(self, multiparams, params)
  File "c:\users\kusuma mulpuru\microblog\venv\lib\site-packages\sqlalchemy\sql\elements.py", line 287, in _execute_on_connection
    return connection._execute_clauseelement(self, multiparams, params)
  File "c:\users\kusuma mulpuru\microblog\venv\lib\site-packages\sqlalchemy\engine\base.py", line 1101, in _execute_clauseelement
    distilled_params,
  File "c:\users\kusuma mulpuru\microblog\venv\lib\site-packages\sqlalchemy\engine\base.py", line 1250, in _execute_context
    e, statement, parameters, cursor, context
  File "c:\users\kusuma mulpuru\microblog\venv\lib\site-packages\sqlalchemy\engine\base.py", line 1476, in _handle_dbapi_exception
    util.raise_from_cause(sqlalchemy_exception, exc_info)
  File "c:\users\kusuma mulpuru\microblog\venv\lib\site-packages\sqlalchemy\util\compat.py", line 398, in raise_from_cause
    reraise(type(exception), exception, tb=exc_tb, cause=cause)
  File "c:\users\kusuma mulpuru\microblog\venv\lib\site-packages\sqlalchemy\util\compat.py", line 152, in reraise
    raise value.with_traceback(tb)
  File "c:\users\kusuma mulpuru\microblog\venv\lib\site-packages\sqlalchemy\engine\base.py", line 1246, in _execute_context
    cursor, statement, parameters, context
  File "c:\users\kusuma mulpuru\microblog\venv\lib\site-packages\sqlalchemy\engine\default.py", line 581, in do_execute
    cursor.execute(statement, parameters)
sqlalchemy.exc.OperationalError: (sqlite3.OperationalError) no such table: contact
[SQL: INSERT INTO contact (user_id, username, contact_text) VALUES (?, ?, ?)]
[parameters: (None, 'kusu', 'dsfsf')]
(Background on this error at: http://sqlalche.me/e/e3q8)
2019-12-14 23:37:33,672 INFO: Microblog startup [in C:\Users\kusuma Mulpuru\microblog\app\__init__.py:49]
2019-12-14 23:40:16,948 INFO: Microblog startup [in C:\Users\kusuma Mulpuru\microblog\app\__init__.py:49]
2019-12-14 23:41:00,336 INFO: Microblog startup [in C:\Users\kusuma Mulpuru\microblog\app\__init__.py:49]
