2019-12-14 21:24:56,080 INFO: Microblog startup [in C:\Users\kusuma Mulpuru\microblog\app\__init__.py:49]
2019-12-14 21:29:08,939 INFO: Microblog startup [in C:\Users\kusuma Mulpuru\microblog\app\__init__.py:49]
2019-12-14 21:32:56,577 INFO: Microblog startup [in C:\Users\kusuma Mulpuru\microblog\app\__init__.py:49]
2019-12-14 21:46:54,670 INFO: Microblog startup [in C:\Users\kusuma Mulpuru\microblog\app\__init__.py:49]
2019-12-14 21:50:42,194 INFO: Microblog startup [in C:\Users\kusuma Mulpuru\microblog\app\__init__.py:49]
2019-12-14 21:54:56,312 INFO: Microblog startup [in C:\Users\kusuma Mulpuru\microblog\app\__init__.py:49]
2019-12-14 22:15:51,868 INFO: Microblog startup [in C:\Users\kusuma Mulpuru\microblog\app\__init__.py:49]
2019-12-14 22:17:18,129 INFO: Microblog startup [in C:\Users\kusuma Mulpuru\microblog\app\__init__.py:49]
2019-12-14 22:18:54,480 INFO: Microblog startup [in C:\Users\kusuma Mulpuru\microblog\app\__init__.py:49]
2019-12-14 22:19:46,647 INFO: Microblog startup [in C:\Users\kusuma Mulpuru\microblog\app\__init__.py:49]
2019-12-14 22:28:47,912 INFO: Microblog startup [in C:\Users\kusuma Mulpuru\microblog\app\__init__.py:49]
2019-12-14 22:36:02,374 INFO: Microblog startup [in C:\Users\kusuma Mulpuru\microblog\app\__init__.py:49]
2019-12-14 23:04:16,213 INFO: Microblog startup [in C:\Users\kusuma Mulpuru\microblog\app\__init__.py:49]
2019-12-14 23:10:51,311 INFO: Microblog startup [in C:\Users\kusuma Mulpuru\microblog\app\__init__.py:49]
2019-12-14 23:12:11,577 INFO: Microblog startup [in C:\Users\kusuma Mulpuru\microblog\app\__init__.py:49]
2019-12-14 23:12:58,792 ERROR: Exception on /feedback [POST] [in c:\users\kusuma mulpuru\microblog\venv\lib\site-packages\flask\app.py:1891]
Traceback (most recent call last):
  File "c:\users\kusuma mulpuru\microblog\venv\lib\site-packages\sqlalchemy\engine\base.py", line 1246, in _execute_context
    cursor, statement, parameters, context
  File "c:\users\kusuma mulpuru\microblog\venv\lib\site-packages\sqlalchemy\engine\default.py", line 581, in do_execute
    cursor.execute(statement, parameters)
sqlite3.OperationalError: no such table: feedback

The above exception was the direct cause of the following exception:

Traceback (most recent call last):
  File "c:\users\kusuma mulpuru\microblog\venv\lib\site-packages\flask\app.py", line 2446, in wsgi_app
    response = self.full_dispatch_request()
  File "c:\users\kusuma mulpuru\microblog\venv\lib\site-packages\flask\app.py", line 1951, in full_dispatch_request
    rv = self.handle_user_exception(e)
  File "c:\users\kusuma mulpuru\microblog\venv\lib\site-packages\flask\app.py", line 1820, in handle_user_exception
    reraise(exc_type, exc_value, tb)
  File "c:\users\kusuma mulpuru\microblog\venv\lib\site-packages\flask\_compat.py", line 39, in reraise
    raise value
  File "c:\users\kusuma mulpuru\microblog\venv\lib\site-packages\flask\app.py", line 1949, in full_dispatch_request
    rv = self.dispatch_request()
  File "c:\users\kusuma mulpuru\microblog\venv\lib\site-packages\flask\app.py", line 1935, in dispatch_request
    return self.view_functions[rule.endpoint](**req.view_args)
  File "C:\Users\kusuma Mulpuru\microblog\app\routes.py", line 200, in feedback
    db.session.commit()
  File "c:\users\kusuma mulpuru\microblog\venv\lib\site-packages\sqlalchemy\orm\scoping.py", line 162, in do
    return getattr(self.registry(), name)(*args, **kwargs)
  File "c:\users\kusuma mulpuru\microblog\venv\lib\site-packages\sqlalchemy\orm\session.py", line 1027, in commit
    self.transaction.commit()
  File "c:\users\kusuma mulpuru\microblog\venv\lib\site-packages\sqlalchemy\orm\session.py", line 494, in commit
    self._prepare_impl()
  File "c:\users\kusuma mulpuru\microblog\venv\lib\site-packages\sqlalchemy\orm\session.py", line 473, in _prepare_impl
    self.session.flush()
  File "c:\users\kusuma mulpuru\microblog\venv\lib\site-packages\sqlalchemy\orm\session.py", line 2470, in flush
    self._flush(objects)
  File "c:\users\kusuma mulpuru\microblog\venv\lib\site-packages\sqlalchemy\orm\session.py", line 2608, in _flush
    transaction.rollback(_capture_exception=True)
  File "c:\users\kusuma mulpuru\microblog\venv\lib\site-packages\sqlalchemy\util\langhelpers.py", line 68, in __exit__
    compat.reraise(exc_type, exc_value, exc_tb)
  File "c:\users\kusuma mulpuru\microblog\venv\lib\site-packages\sqlalchemy\util\compat.py", line 153, in reraise
    raise value
  File "c:\users\kusuma mulpuru\microblog\venv\lib\site-packages\sqlalchemy\orm\session.py", line 2568, in _flush
    flush_context.execute()
  File "c:\users\kusuma mulpuru\microblog\venv\lib\site-packages\sqlalchemy\orm\unitofwork.py", line 422, in execute
    rec.execute(self)
  File "c:\users\kusuma mulpuru\microblog\venv\lib\site-packages\sqlalchemy\orm\unitofwork.py", line 589, in execute
    uow,
  File "c:\users\kusuma mulpuru\microblog\venv\lib\site-packages\sqlalchemy\orm\persistence.py", line 245, in save_obj
    insert,
  File "c:\users\kusuma mulpuru\microblog\venv\lib\site-packages\sqlalchemy\orm\persistence.py", line 1137, in _emit_insert_statements
    statement, params
  File "c:\users\kusuma mulpuru\microblog\venv\lib\site-packages\sqlalchemy\engine\base.py", line 982, in execute
    return meth(self, multiparams, params)
  File "c:\users\kusuma mulpuru\microblog\venv\lib\site-packages\sqlalchemy\sql\elements.py", line 287, in _execute_on_connection
    return connection._execute_clauseelement(self, multiparams, params)
  File "c:\users\kusuma mulpuru\microblog\venv\lib\site-packages\sqlalchemy\engine\base.py", line 1101, in _execute_clauseelement
    distilled_params,
  File "c:\users\kusuma mulpuru\microblog\venv\lib\site-packages\sqlalchemy\engine\base.py", line 1250, in _execute_context
    e, statement, parameters, cursor, context
  File "c:\users\kusuma mulpuru\microblog\venv\lib\site-packages\sqlalchemy\engine\base.py", line 1476, in _handle_dbapi_exception
    util.raise_from_cause(sqlalchemy_exception, exc_info)
  File "c:\users\kusuma mulpuru\microblog\venv\lib\site-packages\sqlalchemy\util\compat.py", line 398, in raise_from_cause
    reraise(type(exception), exception, tb=exc_tb, cause=cause)
  File "c:\users\kusuma mulpuru\microblog\venv\lib\site-packages\sqlalchemy\util\compat.py", line 152, in reraise
    raise value.with_traceback(tb)
  File "c:\users\kusuma mulpuru\microblog\venv\lib\site-packages\sqlalchemy\engine\base.py", line 1246, in _execute_context
    cursor, statement, parameters, context
  File "c:\users\kusuma mulpuru\microblog\venv\lib\site-packages\sqlalchemy\engine\default.py", line 581, in do_execute
    cursor.execute(statement, parameters)
sqlalchemy.exc.OperationalError: (sqlite3.OperationalError) no such table: feedback
[SQL: INSERT INTO feedback (user_id, username, feedback_text) VALUES (?, ?, ?)]
[parameters: (None, 'chandana', 'good')]
(Background on this error at: http://sqlalche.me/e/e3q8)
2019-12-14 23:15:48,591 INFO: Microblog startup [in C:\Users\kusuma Mulpuru\microblog\app\__init__.py:49]
2019-12-14 23:17:16,983 INFO: Microblog startup [in C:\Users\kusuma Mulpuru\microblog\app\__init__.py:49]
2019-12-14 23:22:08,700 INFO: Microblog startup [in C:\Users\kusuma Mulpuru\microblog\app\__init__.py:49]
